<?xml version="1.0" ?>
<!-- =================================================================================== -->
<!-- |    This document was autogenerated by xacro from sw_bd0.xacro                   | -->
<!-- |    EDITING THIS FILE BY HAND IS NOT RECOMMENDED                                 | -->
<!-- =================================================================================== -->
<robot name="sw_bd0">
  <material name="silver">
    <color rgba="0.700 0.700 0.700 1.000"/>
  </material>
  <transmission name="neck_pitch_tran">
    <type>transmission_interface/SimpleTransmission</type>
    <joint name="neck_pitch">
      <hardwareInterface>hardware_interface/EffortJointInterface</hardwareInterface>
    </joint>
    <actuator name="neck_pitch_actr">
      <hardwareInterface>hardware_interface/EffortJointInterface</hardwareInterface>
      <mechanicalReduction>1</mechanicalReduction>
    </actuator>
  </transmission>
  <transmission name="head_pitch_tran">
    <type>transmission_interface/SimpleTransmission</type>
    <joint name="head_pitch">
      <hardwareInterface>hardware_interface/EffortJointInterface</hardwareInterface>
    </joint>
    <actuator name="head_pitch_actr">
      <hardwareInterface>hardware_interface/EffortJointInterface</hardwareInterface>
      <mechanicalReduction>1</mechanicalReduction>
    </actuator>
  </transmission>
  <transmission name="head_yaw_tran">
    <type>transmission_interface/SimpleTransmission</type>
    <joint name="head_yaw">
      <hardwareInterface>hardware_interface/EffortJointInterface</hardwareInterface>
    </joint>
    <actuator name="head_yaw_actr">
      <hardwareInterface>hardware_interface/EffortJointInterface</hardwareInterface>
      <mechanicalReduction>1</mechanicalReduction>
    </actuator>
  </transmission>
  <transmission name="head_roll_tran">
    <type>transmission_interface/SimpleTransmission</type>
    <joint name="head_roll">
      <hardwareInterface>hardware_interface/EffortJointInterface</hardwareInterface>
    </joint>
    <actuator name="head_roll_actr">
      <hardwareInterface>hardware_interface/EffortJointInterface</hardwareInterface>
      <mechanicalReduction>1</mechanicalReduction>
    </actuator>
  </transmission>
  <transmission name="r_hip_ie_tran">
    <type>transmission_interface/SimpleTransmission</type>
    <joint name="r_hip_ie">
      <hardwareInterface>hardware_interface/EffortJointInterface</hardwareInterface>
    </joint>
    <actuator name="r_hip_ie_actr">
      <hardwareInterface>hardware_interface/EffortJointInterface</hardwareInterface>
      <mechanicalReduction>1</mechanicalReduction>
    </actuator>
  </transmission>
  <transmission name="l_hip_ie_tran">
    <type>transmission_interface/SimpleTransmission</type>
    <joint name="l_hip_ie">
      <hardwareInterface>hardware_interface/EffortJointInterface</hardwareInterface>
    </joint>
    <actuator name="l_hip_ie_actr">
      <hardwareInterface>hardware_interface/EffortJointInterface</hardwareInterface>
      <mechanicalReduction>1</mechanicalReduction>
    </actuator>
  </transmission>
  <transmission name="r_hip_aa_tran">
    <type>transmission_interface/SimpleTransmission</type>
    <joint name="r_hip_aa">
      <hardwareInterface>hardware_interface/EffortJointInterface</hardwareInterface>
    </joint>
    <actuator name="r_hip_aa_actr">
      <hardwareInterface>hardware_interface/EffortJointInterface</hardwareInterface>
      <mechanicalReduction>1</mechanicalReduction>
    </actuator>
  </transmission>
  <transmission name="l_hip_aa_tran">
    <type>transmission_interface/SimpleTransmission</type>
    <joint name="l_hip_aa">
      <hardwareInterface>hardware_interface/EffortJointInterface</hardwareInterface>
    </joint>
    <actuator name="l_hip_aa_actr">
      <hardwareInterface>hardware_interface/EffortJointInterface</hardwareInterface>
      <mechanicalReduction>1</mechanicalReduction>
    </actuator>
  </transmission>
  <transmission name="r_hip_fe_tran">
    <type>transmission_interface/SimpleTransmission</type>
    <joint name="r_hip_fe">
      <hardwareInterface>hardware_interface/EffortJointInterface</hardwareInterface>
    </joint>
    <actuator name="r_hip_fe_actr">
      <hardwareInterface>hardware_interface/EffortJointInterface</hardwareInterface>
      <mechanicalReduction>1</mechanicalReduction>
    </actuator>
  </transmission>
  <transmission name="l_hip_fe_tran">
    <type>transmission_interface/SimpleTransmission</type>
    <joint name="l_hip_fe">
      <hardwareInterface>hardware_interface/EffortJointInterface</hardwareInterface>
    </joint>
    <actuator name="l_hip_fe_actr">
      <hardwareInterface>hardware_interface/EffortJointInterface</hardwareInterface>
      <mechanicalReduction>1</mechanicalReduction>
    </actuator>
  </transmission>
  <transmission name="r_knee_fe_tran">
    <type>transmission_interface/SimpleTransmission</type>
    <joint name="r_knee_fe">
      <hardwareInterface>hardware_interface/EffortJointInterface</hardwareInterface>
    </joint>
    <actuator name="r_knee_fe_actr">
      <hardwareInterface>hardware_interface/EffortJointInterface</hardwareInterface>
      <mechanicalReduction>1</mechanicalReduction>
    </actuator>
  </transmission>
  <transmission name="l_knee_fe_tran">
    <type>transmission_interface/SimpleTransmission</type>
    <joint name="l_knee_fe">
      <hardwareInterface>hardware_interface/EffortJointInterface</hardwareInterface>
    </joint>
    <actuator name="l_knee_fe_actr">
      <hardwareInterface>hardware_interface/EffortJointInterface</hardwareInterface>
      <mechanicalReduction>1</mechanicalReduction>
    </actuator>
  </transmission>
  <transmission name="r_foot_fe_tran">
    <type>transmission_interface/SimpleTransmission</type>
    <joint name="r_foot_fe">
      <hardwareInterface>hardware_interface/EffortJointInterface</hardwareInterface>
    </joint>
    <actuator name="r_foot_fe_actr">
      <hardwareInterface>hardware_interface/EffortJointInterface</hardwareInterface>
      <mechanicalReduction>1</mechanicalReduction>
    </actuator>
  </transmission>
  <transmission name="l_foot_fe_tran">
    <type>transmission_interface/SimpleTransmission</type>
    <joint name="l_foot_fe">
      <hardwareInterface>hardware_interface/EffortJointInterface</hardwareInterface>
    </joint>
    <actuator name="l_foot_fe_actr">
      <hardwareInterface>hardware_interface/EffortJointInterface</hardwareInterface>
      <mechanicalReduction>1</mechanicalReduction>
    </actuator>
  </transmission>
  <gazebo>
    <plugin filename="libgazebo_ros_control.so" name="control"/>
  </gazebo>
  <gazebo reference="base_link">
    <material>Gazebo/Silver</material>
    <mu1>0.2</mu1>
    <mu2>0.2</mu2>
    <selfCollide>true</selfCollide>
    <gravity>true</gravity>
  </gazebo>
  <gazebo reference="Neck-Base_1_1_1">
    <material>Gazebo/Silver</material>
    <mu1>0.2</mu1>
    <mu2>0.2</mu2>
    <selfCollide>true</selfCollide>
  </gazebo>
  <gazebo reference="Neck-Cable-Guide_1_1_1">
    <material>Gazebo/Silver</material>
    <mu1>0.2</mu1>
    <mu2>0.2</mu2>
    <selfCollide>true</selfCollide>
  </gazebo>
  <gazebo reference="Head-Yaw-Mount_1_1_1">
    <material>Gazebo/Silver</material>
    <mu1>0.2</mu1>
    <mu2>0.2</mu2>
    <selfCollide>true</selfCollide>
  </gazebo>
  <gazebo reference="Head-Roll-Mount_1_1_1">
    <material>Gazebo/Silver</material>
    <mu1>0.2</mu1>
    <mu2>0.2</mu2>
    <selfCollide>true</selfCollide>
  </gazebo>
  <gazebo reference="Hip-Joint-Yaw-Right_1_1_1">
    <material>Gazebo/Silver</material>
    <mu1>0.2</mu1>
    <mu2>0.2</mu2>
    <selfCollide>true</selfCollide>
  </gazebo>
  <gazebo reference="Hip-Joint-Yaw-Left_1_1_1">
    <material>Gazebo/Silver</material>
    <mu1>0.2</mu1>
    <mu2>0.2</mu2>
    <selfCollide>true</selfCollide>
  </gazebo>
  <gazebo reference="Hip-Joint-Roll-Right_1_1_1">
    <material>Gazebo/Silver</material>
    <mu1>0.2</mu1>
    <mu2>0.2</mu2>
    <selfCollide>true</selfCollide>
  </gazebo>
  <gazebo reference="Hip-Joint-Roll-Left_1_1_1">
    <material>Gazebo/Silver</material>
    <mu1>0.2</mu1>
    <mu2>0.2</mu2>
    <selfCollide>true</selfCollide>
  </gazebo>
  <gazebo reference="Upper-Leg-Right_1_1_1">
    <material>Gazebo/Silver</material>
    <mu1>0.2</mu1>
    <mu2>0.2</mu2>
    <selfCollide>true</selfCollide>
  </gazebo>
  <gazebo reference="Upper-Leg-Left_1_1_1">
    <material>Gazebo/Silver</material>
    <mu1>0.2</mu1>
    <mu2>0.2</mu2>
    <selfCollide>true</selfCollide>
  </gazebo>
  <gazebo reference="Lower-Leg-Right_1_1_1">
    <material>Gazebo/Silver</material>
    <mu1>0.2</mu1>
    <mu2>0.2</mu2>
    <selfCollide>true</selfCollide>
  </gazebo>
  <gazebo reference="Lower-Leg-Left_1_1_1">
    <material>Gazebo/Silver</material>
    <mu1>0.2</mu1>
    <mu2>0.2</mu2>
    <selfCollide>true</selfCollide>
  </gazebo>
  <gazebo reference="Foot-Right_1_1_1">
    <material>Gazebo/Silver</material>
    <mu1>0.2</mu1>
    <mu2>0.2</mu2>
    <selfCollide>true</selfCollide>
  </gazebo>
  <gazebo reference="Foot-Left_1_1_1">
    <material>Gazebo/Silver</material>
    <mu1>0.2</mu1>
    <mu2>0.2</mu2>
    <selfCollide>true</selfCollide>
  </gazebo>
  <link name="base_link">
    <inertial>
      <origin rpy="0 0 0" xyz="0.00030692869034494455 0.10794443945855599 0.336408641271748"/>
      <mass value="58.84948927612512"/>
      <inertia ixx="0.742119" ixy="0.001524" ixz="-0.001048" iyy="0.390167" iyz="-0.019101" izz="0.598148"/>
    </inertial>
    <visual>
      <origin rpy="0 0 0" xyz="0 0 0"/>
      <geometry>
        <mesh filename="package://duckling_description/meshes/base_link.stl" scale="0.001 0.001 0.001"/>
      </geometry>
      <material name="silver"/>
    </visual>
    <collision>
      <origin rpy="0 0 0" xyz="0 0 0"/>
      <geometry>
        <mesh filename="package://duckling_description/meshes/base_link.stl" scale="0.001 0.001 0.001"/>
      </geometry>
    </collision>
  </link>
  <link name="Neck-Base_1_1_1">
    <inertial>
      <origin rpy="0 0 0" xyz="-0.0037204185899173013 0.022877173720960785 0.05313044025265656"/>
      <mass value="1.7744309148890365"/>
      <inertia ixx="0.003949" ixy="-0.000188" ixz="-0.000416" iyy="0.003277" iyz="-0.001327" izz="0.001342"/>
    </inertial>
    <visual>
      <origin rpy="0 0 0" xyz="0.0013 -0.023577 -0.394589"/>
      <geometry>
        <mesh filename="package://duckling_description/meshes/Neck-Base_1_1_1.stl" scale="0.001 0.001 0.001"/>
      </geometry>
      <material name="silver"/>
    </visual>
    <collision>
      <origin rpy="0 0 0" xyz="0.0013 -0.023577 -0.394589"/>
      <geometry>
        <mesh filename="package://duckling_description/meshes/Neck-Base_1_1_1.stl" scale="0.001 0.001 0.001"/>
      </geometry>
    </collision>
  </link>
  <link name="Neck-Cable-Guide_1_1_1">
    <inertial>
      <origin rpy="0 0 0" xyz="0.02567570325608754 0.007067867979778403 0.01272355868039865"/>
      <mass value="0.5403874707456671"/>
      <inertia ixx="0.000118" ixy="-0.0" ixz="-0.0" iyy="0.000203" iyz="-1.9e-05" izz="0.00021"/>
    </inertial>
    <visual>
      <origin rpy="0 0 0" xyz="0.025 -0.0886 -0.505469"/>
      <geometry>
        <mesh filename="package://duckling_description/meshes/Neck-Cable-Guide_1_1_1.stl" scale="0.001 0.001 0.001"/>
      </geometry>
      <material name="silver"/>
    </visual>
    <collision>
      <origin rpy="0 0 0" xyz="0.025 -0.0886 -0.505469"/>
      <geometry>
        <mesh filename="package://duckling_description/meshes/Neck-Cable-Guide_1_1_1.stl" scale="0.001 0.001 0.001"/>
      </geometry>
    </collision>
  </link>
  <link name="Head-Yaw-Mount_1_1_1">
    <inertial>
      <origin rpy="0 0 0" xyz="-3.900737921020531e-05 0.003677385711655906 0.02242369852722459"/>
      <mass value="0.7884788831732902"/>
      <inertia ixx="0.000545" ixy="0.0" ixz="0.0" iyy="0.000245" iyz="-1e-05" izz="0.00055"/>
    </inertial>
    <visual>
      <origin rpy="0 0 0" xyz="-0.0007 -0.0883 -0.532569"/>
      <geometry>
        <mesh filename="package://duckling_description/meshes/Head-Yaw-Mount_1_1_1.stl" scale="0.001 0.001 0.001"/>
      </geometry>
      <material name="silver"/>
    </visual>
    <collision>
      <origin rpy="0 0 0" xyz="-0.0007 -0.0883 -0.532569"/>
      <geometry>
        <mesh filename="package://duckling_description/meshes/Head-Yaw-Mount_1_1_1.stl" scale="0.001 0.001 0.001"/>
      </geometry>
    </collision>
  </link>
  <link name="Head-Roll-Mount_1_1_1">
    <inertial>
      <origin rpy="0 0 0" xyz="-0.0005152725386995515 -0.05157951540531315 0.005136350911904786"/>
      <mass value="5.0942155694527305"/>
      <inertia ixx="0.039562" ixy="2e-05" ixz="9e-06" iyy="0.030187" iyz="0.001552" izz="0.063238"/>
    </inertial>
    <visual>
      <origin rpy="0 0 0" xyz="-0.00065 -0.133848 -0.562209"/>
      <geometry>
        <mesh filename="package://duckling_description/meshes/Head-Roll-Mount_1_1_1.stl" scale="0.001 0.001 0.001"/>
      </geometry>
      <material name="silver"/>
    </visual>
    <collision>
      <origin rpy="0 0 0" xyz="-0.00065 -0.133848 -0.562209"/>
      <geometry>
        <mesh filename="package://duckling_description/meshes/Head-Roll-Mount_1_1_1.stl" scale="0.001 0.001 0.001"/>
      </geometry>
    </collision>
  </link>
  <link name="Hip-Joint-Yaw-Right_1_1_1">
    <inertial>
      <origin rpy="0 0 0" xyz="-0.0034769226818922236 0.005329819672309374 -0.05718740698283692"/>
      <mass value="2.710413234826848"/>
      <inertia ixx="0.00322" ixy="4e-06" ixz="-4.3e-05" iyy="0.004455" iyz="3e-05" izz="0.001963"/>
    </inertial>
    <visual>
      <origin rpy="0 0 0" xyz="0.046658 -0.113027 -0.350727"/>
      <geometry>
        <mesh filename="package://duckling_description/meshes/Hip-Joint-Yaw-Right_1_1_1.stl" scale="0.001 0.001 0.001"/>
      </geometry>
      <material name="silver"/>
    </visual>
    <collision>
      <origin rpy="0 0 0" xyz="0.046658 -0.113027 -0.350727"/>
      <geometry>
        <mesh filename="package://duckling_description/meshes/Hip-Joint-Yaw-Right_1_1_1.stl" scale="0.001 0.001 0.001"/>
      </geometry>
    </collision>
  </link>
  <link name="Hip-Joint-Yaw-Left_1_1_1">
    <inertial>
      <origin rpy="0 0 0" xyz="0.003476916493858888 0.005329817672092077 -0.05718740567578556"/>
      <mass value="2.7104129345182724"/>
      <inertia ixx="0.00322" ixy="-4e-06" ixz="4.3e-05" iyy="0.004455" iyz="3e-05" izz="0.001963"/>
    </inertial>
    <visual>
      <origin rpy="0 0 0" xyz="-0.046658 -0.113027 -0.350727"/>
      <geometry>
        <mesh filename="package://duckling_description/meshes/Hip-Joint-Yaw-Left_1_1_1.stl" scale="0.001 0.001 0.001"/>
      </geometry>
      <material name="silver"/>
    </visual>
    <collision>
      <origin rpy="0 0 0" xyz="-0.046658 -0.113027 -0.350727"/>
      <geometry>
        <mesh filename="package://duckling_description/meshes/Hip-Joint-Yaw-Left_1_1_1.stl" scale="0.001 0.001 0.001"/>
      </geometry>
    </collision>
  </link>
  <link name="Hip-Joint-Roll-Right_1_1_1">
    <inertial>
      <origin rpy="0 0 0" xyz="-0.037585464304248785 -0.008742267643225526 0.0005073004766671385"/>
      <mass value="1.2525665319575874"/>
      <inertia ixx="0.000491" ixy="8.9e-05" ixz="4e-06" iyy="0.001604" iyz="2e-06" izz="0.001478"/>
    </inertial>
    <visual>
      <origin rpy="0 0 0" xyz="0.049408 -0.107827 -0.287377"/>
      <geometry>
        <mesh filename="package://duckling_description/meshes/Hip-Joint-Roll-Right_1_1_1.stl" scale="0.001 0.001 0.001"/>
      </geometry>
      <material name="silver"/>
    </visual>
    <collision>
      <origin rpy="0 0 0" xyz="0.049408 -0.107827 -0.287377"/>
      <geometry>
        <mesh filename="package://duckling_description/meshes/Hip-Joint-Roll-Right_1_1_1.stl" scale="0.001 0.001 0.001"/>
      </geometry>
    </collision>
  </link>
  <link name="Hip-Joint-Roll-Left_1_1_1">
    <inertial>
      <origin rpy="0 0 0" xyz="0.03758545882228228 -0.008742267643225513 0.0005073004766672495"/>
      <mass value="1.2525665319575872"/>
      <inertia ixx="0.000491" ixy="-8.9e-05" ixz="-4e-06" iyy="0.001604" iyz="2e-06" izz="0.001478"/>
    </inertial>
    <visual>
      <origin rpy="0 0 0" xyz="-0.049408 -0.107827 -0.287377"/>
      <geometry>
        <mesh filename="package://duckling_description/meshes/Hip-Joint-Roll-Left_1_1_1.stl" scale="0.001 0.001 0.001"/>
      </geometry>
      <material name="silver"/>
    </visual>
    <collision>
      <origin rpy="0 0 0" xyz="-0.049408 -0.107827 -0.287377"/>
      <geometry>
        <mesh filename="package://duckling_description/meshes/Hip-Joint-Roll-Left_1_1_1.stl" scale="0.001 0.001 0.001"/>
      </geometry>
    </collision>
  </link>
  <link name="Upper-Leg-Right_1_1_1">
    <inertial>
      <origin rpy="0 0 0" xyz="-0.01713314425618992 0.033955639219308775 -0.03420329511266973"/>
      <mass value="9.797710752447612"/>
      <inertia ixx="0.045664" ixy="-0.000209" ixz="-2.8e-05" iyy="0.023224" iyz="0.013684" izz="0.02779"/>
    </inertial>
    <visual>
      <origin rpy="0 0 0" xyz="0.129009 -0.10285 -0.288126"/>
      <geometry>
        <mesh filename="package://duckling_description/meshes/Upper-Leg-Right_1_1_1.stl" scale="0.001 0.001 0.001"/>
      </geometry>
      <material name="silver"/>
    </visual>
    <collision>
      <origin rpy="0 0 0" xyz="0.129009 -0.10285 -0.288126"/>
      <geometry>
        <mesh filename="package://duckling_description/meshes/Upper-Leg-Right_1_1_1.stl" scale="0.001 0.001 0.001"/>
      </geometry>
    </collision>
  </link>
  <link name="Upper-Leg-Left_1_1_1">
    <inertial>
      <origin rpy="0 0 0" xyz="0.017133138774223372 0.033955639219308775 -0.034203295112669785"/>
      <mass value="9.79771075244762"/>
      <inertia ixx="0.045664" ixy="0.000209" ixz="2.8e-05" iyy="0.023224" iyz="0.013684" izz="0.02779"/>
    </inertial>
    <visual>
      <origin rpy="0 0 0" xyz="-0.129009 -0.10285 -0.288126"/>
      <geometry>
        <mesh filename="package://duckling_description/meshes/Upper-Leg-Left_1_1_1.stl" scale="0.001 0.001 0.001"/>
      </geometry>
      <material name="silver"/>
    </visual>
    <collision>
      <origin rpy="0 0 0" xyz="-0.129009 -0.10285 -0.288126"/>
      <geometry>
        <mesh filename="package://duckling_description/meshes/Upper-Leg-Left_1_1_1.stl" scale="0.001 0.001 0.001"/>
      </geometry>
    </collision>
  </link>
  <link name="Lower-Leg-Right_1_1_1">
    <inertial>
      <origin rpy="0 0 0" xyz="0.022337859585607883 -0.021387299875317956 -0.08585627297390336"/>
      <mass value="3.5336559525083544"/>
      <inertia ixx="0.013524" ixy="0.000238" ixz="0.000634" iyy="0.010593" iyz="-0.003425" izz="0.00365"/>
    </inertial>
    <visual>
      <origin rpy="0 0 0" xyz="0.129009 -0.182156 -0.210418"/>
      <geometry>
        <mesh filename="package://duckling_description/meshes/Lower-Leg-Right_1_1_1.stl" scale="0.001 0.001 0.001"/>
      </geometry>
      <material name="silver"/>
    </visual>
    <collision>
      <origin rpy="0 0 0" xyz="0.129009 -0.182156 -0.210418"/>
      <geometry>
        <mesh filename="package://duckling_description/meshes/Lower-Leg-Right_1_1_1.stl" scale="0.001 0.001 0.001"/>
      </geometry>
    </collision>
  </link>
  <link name="Lower-Leg-Left_1_1_1">
    <inertial>
      <origin rpy="0 0 0" xyz="-0.022337864800614962 -0.02138729956553212 -0.08585627245860046"/>
      <mass value="3.533655907847469"/>
      <inertia ixx="0.013524" ixy="-0.000238" ixz="-0.000634" iyy="0.010593" iyz="-0.003425" izz="0.00365"/>
    </inertial>
    <visual>
      <origin rpy="0 0 0" xyz="-0.129009 -0.182156 -0.210418"/>
      <geometry>
        <mesh filename="package://duckling_description/meshes/Lower-Leg-Left_1_1_1.stl" scale="0.001 0.001 0.001"/>
      </geometry>
      <material name="silver"/>
    </visual>
    <collision>
      <origin rpy="0 0 0" xyz="-0.129009 -0.182156 -0.210418"/>
      <geometry>
        <mesh filename="package://duckling_description/meshes/Lower-Leg-Left_1_1_1.stl" scale="0.001 0.001 0.001"/>
      </geometry>
    </collision>
  </link>
  <link name="Foot-Right_1_1_1">
    <inertial>
      <origin rpy="0 0 0" xyz="0.004317818616470584 -0.02253962501094224 -0.05014233472325015"/>
      <mass value="2.196651599731845"/>
      <inertia ixx="0.006073" ixy="0.000115" ixz="0.000495" iyy="0.00203" iyz="-0.000449" izz="0.005022"/>
    </inertial>
    <visual>
      <origin rpy="0 0 0" xyz="0.117018 -0.137149 -0.080276"/>
      <geometry>
        <mesh filename="package://duckling_description/meshes/Foot-Right_1_1_1.stl" scale="0.001 0.001 0.001"/>
      </geometry>
      <material name="silver"/>
    </visual>
    <collision>
      <origin rpy="0 0 0" xyz="0.117018 -0.137149 -0.080276"/>
      <geometry>
        <mesh filename="package://duckling_description/meshes/Foot-Right_1_1_1.stl" scale="0.001 0.001 0.001"/>
      </geometry>
    </collision>
  </link>
  <link name="Foot-Left_1_1_1">
    <inertial>
      <origin rpy="0 0 0" xyz="-0.004317824098437145 -0.02253962501094224 -0.05014233472325014"/>
      <mass value="2.196651599731846"/>
      <inertia ixx="0.006073" ixy="-0.000115" ixz="-0.000495" iyy="0.00203" iyz="-0.000449" izz="0.005022"/>
    </inertial>
    <visual>
      <origin rpy="0 0 0" xyz="-0.117018 -0.137149 -0.080276"/>
      <geometry>
        <mesh filename="package://duckling_description/meshes/Foot-Left_1_1_1.stl" scale="0.001 0.001 0.001"/>
      </geometry>
      <material name="silver"/>
    </visual>
    <collision>
      <origin rpy="0 0 0" xyz="-0.117018 -0.137149 -0.080276"/>
      <geometry>
        <mesh filename="package://duckling_description/meshes/Foot-Left_1_1_1.stl" scale="0.001 0.001 0.001"/>
      </geometry>
    </collision>
  </link>
  <joint name="neck_pitch" type="revolute">
    <origin rpy="0 0 0" xyz="-0.0013 0.023577 0.394589"/>
    <limit velocity="1000" lower="-3.14" upper="3.14" effort="1000"/>
    <parent link="base_link"/>
    <child link="Neck-Base_1_1_1"/>
    <axis xyz="-1.0 0.0 0.0"/>
  </joint>
  <joint name="head_pitch" type="revolute">
    <origin rpy="0 0 0" xyz="-0.0237 0.065023 0.11088"/>
    <limit velocity="1000" lower="-3.14" upper="3.14" effort="1000"/>
    <parent link="Neck-Base_1_1_1"/>
    <child link="Neck-Cable-Guide_1_1_1"/>
    <axis xyz="1.0 0.0 0.0"/>
  </joint>
  <joint name="head_yaw" type="revolute">
    <origin rpy="0 0 0" xyz="0.0257 -0.0003 0.0271"/>
    <limit velocity="1000" lower="-3.14" upper="3.14" effort="1000"/>
    <parent link="Neck-Cable-Guide_1_1_1"/>
    <child link="Head-Yaw-Mount_1_1_1"/>
    <axis xyz="-0.0 0.0 1.0"/>
  </joint>
  <joint name="head_roll" type="revolute">
    <origin rpy="0 0 0" xyz="-5e-05 0.045548 0.02964"/>
    <limit velocity="1000" lower="-3.14" upper="3.14" effort="1000"/>
    <parent link="Head-Yaw-Mount_1_1_1"/>
    <child link="Head-Roll-Mount_1_1_1"/>
    <axis xyz="-0.0 1.0 0.000175"/>
  </joint>
  <joint name="r_hip_ie" type="revolute">
    <origin rpy="0 0 0" xyz="-0.046658 0.113027 0.350727"/>
    <limit velocity="1000" lower="-3.14" upper="3.14" effort="1000"/>
    <parent link="base_link"/>
    <child link="Hip-Joint-Yaw-Right_1_1_1"/>
    <axis xyz="0.0 -0.0 -1.0"/>
  </joint>
  <joint name="l_hip_ie" type="revolute">
    <origin rpy="0 0 0" xyz="0.046658 0.113027 0.350727"/>
    <limit velocity="1000" lower="-3.14" upper="3.14" effort="1000"/>
    <parent link="base_link"/>
    <child link="Hip-Joint-Yaw-Left_1_1_1"/>
    <axis xyz="-0.0 -0.0 -1.0"/>
  </joint>
  <joint name="r_hip_aa" type="revolute">
    <origin rpy="0 0 0" xyz="-0.00275 -0.0052 -0.06335"/>
    <limit velocity="1000" lower="-3.14" upper="3.14" effort="1000"/>
    <parent link="Hip-Joint-Yaw-Right_1_1_1"/>
    <child link="Hip-Joint-Roll-Right_1_1_1"/>
    <axis xyz="0.0 -1.0 -0.0"/>
  </joint>
  <joint name="l_hip_aa" type="revolute">
    <origin rpy="0 0 0" xyz="0.00275 -0.0052 -0.06335"/>
    <limit velocity="1000" lower="-3.14" upper="3.14" effort="1000"/>
    <parent link="Hip-Joint-Yaw-Left_1_1_1"/>
    <child link="Hip-Joint-Roll-Left_1_1_1"/>
    <axis xyz="-0.0 -1.0 -0.0"/>
  </joint>
  <joint name="r_hip_fe" type="revolute">
    <origin rpy="0 0 0" xyz="-0.079601 -0.004977 0.000749"/>
    <limit velocity="1000" lower="-3.14" upper="3.14" effort="1000"/>
    <parent link="Hip-Joint-Roll-Right_1_1_1"/>
    <child link="Upper-Leg-Right_1_1_1"/>
    <axis xyz="-1.0 -0.0 0.0"/>
  </joint>
  <joint name="l_hip_fe" type="revolute">
    <origin rpy="0 0 0" xyz="0.079601 -0.004977 0.000749"/>
    <limit velocity="1000" lower="-3.14" upper="3.14" effort="1000"/>
    <parent link="Hip-Joint-Roll-Left_1_1_1"/>
    <child link="Upper-Leg-Left_1_1_1"/>
    <axis xyz="1.0 -0.0 0.0"/>
  </joint>
  <joint name="r_knee_fe" type="revolute">
    <origin rpy="0 0 0" xyz="0.0 0.079306 -0.077708"/>
    <limit velocity="1000" lower="-3.14" upper="3.14" effort="1000"/>
    <parent link="Upper-Leg-Right_1_1_1"/>
    <child link="Lower-Leg-Right_1_1_1"/>
    <axis xyz="1.0 -0.0 -0.0"/>
  </joint>
  <joint name="l_knee_fe" type="revolute">
    <origin rpy="0 0 0" xyz="0.0 0.079306 -0.077708"/>
    <limit velocity="1000" lower="-3.14" upper="3.14" effort="1000"/>
    <parent link="Upper-Leg-Left_1_1_1"/>
    <child link="Lower-Leg-Left_1_1_1"/>
    <axis xyz="-1.0 -0.0 -0.0"/>
  </joint>
  <joint name="r_foot_fe" type="revolute">
    <origin rpy="0 0 0" xyz="0.011991 -0.045007 -0.130142"/>
    <limit velocity="1000" lower="-3.14" upper="3.14" effort="1000"/>
    <parent link="Lower-Leg-Right_1_1_1"/>
    <child link="Foot-Right_1_1_1"/>
    <axis xyz="-1.0 0.0 -0.0"/>
  </joint>
  <joint name="l_foot_fe" type="revolute">
    <origin rpy="0 0 0" xyz="-0.011991 -0.045007 -0.130142"/>
    <limit velocity="1000" lower="-3.14" upper="3.14" effort="1000"/>
    <parent link="Lower-Leg-Left_1_1_1"/>
    <child link="Foot-Left_1_1_1"/>
    <axis xyz="1.0 0.0 -0.0"/>
  </joint>
  <!-- Contact points on URDF -->
  <link name="l_foot_toe">
    <inertial>
      <origin rpy="0 0 0" xyz="0 0 0"/>
      <mass value="0.0"/>
      <inertia ixx="0.0" ixy="-0.0" ixz="0.0" iyy="0.0" iyz="0.0" izz="0.0"/>
    </inertial>
  </link>
  <link name="l_foot_heel">
    <inertial>
      <origin rpy="0 0 0" xyz="0 0 0"/>
      <mass value="0.0"/>
      <inertia ixx="0.0" ixy="-0.0" ixz="0.0" iyy="0.0" iyz="0.0" izz="0.0"/>
    </inertial>
  </link>
  <joint name="l_toe_ankle" type="fixed">
    <origin rpy="0 0 0" xyz="-0.01 -0.1 -0.07"/>
    <parent link="Foot-Left_1_1_1"/>
    <child link="l_foot_toe"/>
    <axis xyz="1.0 0.0 0.0"/>
  </joint>
  <joint name="l_heel_ankle" type="fixed">
    <origin rpy="0 0 0" xyz="-0.01 0.05 -0.07"/>
    <parent link="Foot-Left_1_1_1"/>
    <child link="l_foot_heel"/>
    <axis xyz="1.0 0.0 0.0"/>
  </joint>
  <link name="r_foot_toe">
    <inertial>
      <origin rpy="0 0 0" xyz="0 0 0"/>
      <mass value="0.0"/>
      <inertia ixx="0.0" ixy="-0.0" ixz="0.0" iyy="0.0" iyz="0.0" izz="0.0"/>
    </inertial>
  </link>
  <link name="r_foot_heel">
    <inertial>
      <origin rpy="0 0 0" xyz="0 0 0"/>
      <mass value="0.0"/>
      <inertia ixx="0.0" ixy="-0.0" ixz="0.0" iyy="0.0" iyz="0.0" izz="0.0"/>
    </inertial>
  </link>
  <joint name="r_toe_ankle" type="fixed">
    <origin rpy="0 0 0" xyz="0.01 -0.1 -0.07"/>
    <parent link="Foot-Right_1_1_1"/>
    <child link="r_foot_toe"/>
    <axis xyz="1.0 0.0 0.0"/>
  </joint>
  <joint name="r_heel_ankle" type="fixed">
    <origin rpy="0 0 0" xyz="0.01 0.05 -0.07"/>
    <parent link="Foot-Right_1_1_1"/>
    <child link="r_foot_heel"/>
    <axis xyz="1.0 0.0 0.0"/>
  </joint>
</robot>
